<?xml version="1.0"?>
<robot name="my_bot">

    <!-- BASE LINK -->
    <link name="base_link">
        <visual>
            <geometry>
                <box size="0.2 0.2 0.05"/>
            </geometry>
        </visual>
        <collision>
            <geometry>
                <box size="0.2 0.2 0.05"/>
            </geometry>
        </collision>
        <inertial>
            <origin xyz="0 0 0" rpy="0 0 0"/>
            <mass value="1.0"/>
            <inertia ixx="0.00166666666667" ixy="0.0" ixz="0.0" 
                     iyy="0.00166666666667" iyz="0.0" 
                     izz="0.00333333333333"/>
        </inertial>
    </link>

    <!-- WHEELS -->
    <joint name="front_right_wheel_joint" type="continuous">
        <parent link="base_link"/>
        <child link="front_left_wheel"/>
        <origin xyz="0.1 0.12 0" rpy="0 0 0"/>
        <axis xyz="0 1 0"/>
    </joint>
    <link name="front_right_wheel">
        <visual>
            <geometry>
                <mesh filename="package://example_gazebo_simulation/description/wheel.stl"/>
            </geometry>

        </visual>
        <collision>
            <geometry>
                <mesh filename="package://example_gazebo_simulation/description/wheel.stl"/>
            </geometry>
        </collision>
        <inertial>
            <origin xyz="0 0 0" rpy="0 0 0"/>
            <mass value="0.1"/>
            <inertia ixx="0.000025" ixy="0.0" ixz="0.0"
                     iyy="0.000025" iyz="0.0"
                     izz="0.00005"/>
        </inertial>
    </link>

    <joint name="front_left_wheel_joint" type="continuous">
        <parent link="base_link"/>
        <child link="front_right_wheel"/>
        <origin xyz="0.1 -0.12 0" rpy="0 0 0"/>
        <axis xyz="0 1 0"/>
    </joint>
    <link name="front_left_wheel">
        <visual>
            <geometry>
                <mesh filename="package://example_gazebo_simulation/description/wheel.stl"/>
            </geometry>
        </visual>
        <collision>
            <geometry>
                <mesh filename="package://example_gazebo_simulation/description/wheel.stl"/>
            </geometry>
        </collision>
        <inertial>
            <origin xyz="0 0 0" rpy="0 0 0"/>
            <mass value="0.1"/>
            <inertia ixx="0.000025" ixy="0.0" ixz="0.0"
                     iyy="0.000025" iyz="0.0"
                     izz="0.00005"/>
        </inertial>
    </link>

    <joint name="rear_right_wheel_joint" type="continuous">
        <parent link="base_link"/>
        <child link="rear_left_wheel"/>
        <origin xyz="-0.1 0.12 0" rpy="0 0 0"/>
        <axis xyz="0 1 0"/>
    </joint>
    <link name="rear_right_wheel">
        <visual>
            <geometry>
                <mesh filename="package://example_gazebo_simulation/description/wheel.stl"/>
            </geometry>
        </visual>
        <collision>
            <geometry>
                <mesh filename="package://example_gazebo_simulation/description/wheel.stl"/>
            </geometry>
        </collision>
        <inertial>
            <origin xyz="0 0 0" rpy="0 0 0"/>
            <mass value="0.1"/>
            <inertia ixx="0.000025" ixy="0.0" ixz="0.0"
                     iyy="0.000025" iyz="0.0"
                     izz="0.00005"/>
        </inertial>
    </link>

    <joint name="rear_left_wheel_joint" type="continuous">
        <parent link="base_link"/>
        <child link="rear_right_wheel"/>
        <origin xyz="-0.1 -0.12 0" rpy="0 0 0"/>
        <axis xyz="0 1 0"/>
    </joint>
    <link name="rear_left_wheel">
        <visual>
            <geometry>
                <mesh filename="package://example_gazebo_simulation/description/wheel.stl"/>
            </geometry>
        </visual>
        <collision>
            <geometry>
                <mesh filename="package://example_gazebo_simulation/description/wheel.stl"/>
            </geometry>
        </collision>
        <inertial>
            <origin xyz="0 0 0" rpy="0 0 0"/>
            <mass value="0.1"/>
            <inertia ixx="0.000025" ixy="0.0" ixz="0.0"
                     iyy="0.000025" iyz="0.0"
                     izz="0.00005"/>
        </inertial>
    </link>

    <!-- ARM LINK -->
    <joint name="arm_joint" type="revolute">
        <parent link="base_link"/>
        <child link="arm"/>
        <origin xyz="0.05 0 0.025" rpy="0 0 0"/>
        <axis xyz="0 1 0"/>
        <limit lower="-1.57079632679" upper="1.57079632679" effort="1.0" velocity="1.0"/>
    </joint>
    <link name="arm">
        <visual>
            <geometry>
                <mesh filename="package://example_gazebo_simulation/description/arm.stl"/>
            </geometry>
        </visual>
        <collision>
            <geometry>
                <mesh filename="package://example_gazebo_simulation/description/arm.stl"/>
            </geometry>
        </collision>
        <inertial>
            <origin xyz="0 0 0" rpy="0 0 0"/>
            <mass value="0.2"/>
            <inertia ixx="0.0001" ixy="0.0" ixz="0.0"
                     iyy="0.0001" iyz="0.0"
                     izz="0.0002"/>
        </inertial>
    </link>

    <!-- REAR CUBE LINK -->
    <joint name="rear_cube_joint" type="prismatic">
        <parent link="base_link"/>
        <child link="rear_cube"/>
        <origin xyz="0 -0.05 0.03" rpy="0 0 0"/>
        <axis xyz="0 1 0"/>
        <limit lower="-0.1" upper="0.1" effort="1.0" velocity="0.5"/>
    </joint>
    <link name="rear_cube">
        <visual>
            <geometry>
                <box size="0.02 0.02 0.02"/>
            </geometry>
        </visual>
        <collision>
            <geometry>
                <box size="0.02 0.02 0.02"/>
            </geometry>
        </collision>
        <inertial>
            <origin xyz="0 0 0" rpy="0 0 0"/>
            <mass value="0.05"/>
            <inertia ixx="0.00000083333333333" ixy="0.0" ixz="0.0"
                     iyy="0.00000083333333333" iyz="0.0"
                     izz="0.00000083333333333"/>
        </inertial>
    </link>

    <ros2_control name="GazeboSystem" type="system">
        <hardware>
            <plugin>gazebo_ros2_control/GazeboSystem</plugin>
        </hardware>
        <joint name="front_left_wheel_joint">
            <command_interface name="velocity">
                <param name="min">-10</param>
                <param name="max">10</param>
            </command_interface>
            <state_interface name="velocity"/>
            <state_interface name="position"/>
        </joint>
        <joint name="front_right_wheel_joint">
            <command_interface name="velocity">
                <param name="min">-10</param>
                <param name="max">10</param>
            </command_interface>
            <state_interface name="velocity"/>
            <state_interface name="position"/>
        </joint>
        <joint name="rear_left_wheel_joint">
            <command_interface name="velocity">
                <param name="min">-10</param>
                <param name="max">10</param>
            </command_interface>
            <state_interface name="velocity"/>
            <state_interface name="position"/>
        </joint>
        <joint name="rear_right_wheel_joint">
            <command_interface name="velocity">
                <param name="min">-10</param>
                <param name="max">10</param>
            </command_interface>
            <state_interface name="velocity"/>
            <state_interface name="position"/>
        </joint>
        <joint name="rear_cube_joint">
            <command_interface name="position">
                <param name="min">-0.05</param>
                <param name="max">0.05</param>
            </command_interface>
            <state_interface name="position"/>
        </joint>
        <joint name="arm_joint">
            <command_interface name="position">
                <param name="min">-1.5708</param>
                <param name="max">1.5708</param>
            </command_interface>
            <state_interface name="position"/>
            <state_interface name="velocity"/>
        </joint> <!-- TODO check if the interface tasg could be integrated in the joints definition -->
    </ros2_control>

    <gazebo>
        <plugin name="gazebo_ros2_control" filename="libgazebo_ros2_control.so">
            <parameters>$(find example_gazebo_simulation)/config/controllers.yaml</parameters>
        </plugin>
    </gazebo>

</robot>
